<?xml version="1.0"?>
<robot xmlns:xacro="http://www.ros.org/wiki/xacro">
    <xacro:include filename="$(find rover0_description)/urdf/rover0_description_common.urdf.xacro" />

    <xacro:property name="wheel_mass" value="0.3" />
    <xacro:property name="wheel_radius" value="0.028" />
    <xacro:property name="wheel_width" value="0.025" />
    <xacro:property name="PI" value="3.1415926535897931"/>

    <xacro:macro name="wheel" params="prefix parent x_reflect y_reflect x_off y_off z_off">
      <link name="${prefix}_wheel_link">
        <xacro:cylinder_inertia m="0.5" r="${wheel_radius}" h="${wheel_width}"/>

        <collision>
          <origin xyz="0 0 0" rpy="0 0 0"/>
          <geometry>
            <sphere radius="${wheel_radius}"/>
          </geometry>
        </collision>

        <visual>
          <origin xyz="0 0 0" rpy="0 0 0"/>
          <geometry>
            <cylinder radius="${wheel_radius}" length="${wheel_width}"/>
          </geometry>
          <material name="black" />
        </visual>
      </link>

      <joint name="${prefix}_wheel_joint" type="continuous">
        <parent link="${parent}" />
        <child link="${prefix}_wheel_link" />
        <origin xyz="${x_reflect*x_off} ${y_reflect * y_off} ${-z_off}" rpy="-${pi/2} 0 0" />
        <axis xyz="0 0 1" />
      </joint>
    </xacro:macro>
</robot>
